Workbook

Sheet สรุปมัดจำอะไหล่ N 67
A1: บริษัท เอกสหกรุ๊ป ออโตโมบิล จำกัด
A2: ณ วันที่ 31 ธันวาคม 2567
A3: ลำดับ | B3: ชื่อลูกค้า | C3: เลขที่มัดจำ | D3: วันที่ | E3: จำนวนเงิน
A4: 1 | B4: กมลรส ขุนพล | C4: 6TB-24050108 | D4: 243767 | E4: -3673.84
A5: 2 | B5: กฤตติกา จงเจริญ | C5: NTB-24010001 | D5: 243622 | E5: -3000
A6: 3 | B6: กฤษณนันท์ นันจรูญ | C6: 3TM-24120033 | D6: 243980 | E6: -828.97
A7: 4 | B7: กันต์ ทิพย์อาภรณ์ | C7: NTB-24070001 | D7: 243802 | E7: -2000
A8: 5 | B8: กานต์ สนิทจันทร์ | C8: 5TM-24120031 | D8: 243979 | E8: -810.28
A9: 6 | B9: กิจการ เต้นท์ รถสวย | C9: 5TB-24030277 | D9: 243706 | E9: -299.6
A10: 7 | B10: กุลนิดา มั่งประยูร | C10: 5TB-24070274 | D10: 243824 | E10: -17300
A11: 8 | B11: เกียรติศักดิ์ นาแก้ว | C11: 6TM-24120019 | D11: 243980 | E11: -18691.59
A12: 9 | B12: คำนวณ เถาวว์ชาลี | C12: 3TV-24120024 | D12: 243976 | E12: -1110
A13: 10 | B13: จารุวัฒน์ สุขวรรณ | C13: 3TV-24120014 | D13: 243967 | E13: -2515
A14: 11 | B14: จิตรพร กิจประยูร | C14: 3TB-24070376 | D14: 243830 | E14: -2418.75
A15: 12 | B15: จิราภา อุดมศิลป์ | C15: NTB-24060001 | D15: 243775 | E15: -2000
... A66: 63 | B66: เอื้อมพร เชาว์ทองหลาง | C66: 3TV-24090013 | D66: 243872 | E66: -952.3
A67: ยอดรวมทั้งหมด | E67: -148491.71

Sheet Sheet5
A1: Row Labels | B1: Sum of สถานะ
A2: ANDREAS MERTENS | B2: 0
A3: ANITA CALEBAG LAPPAY | B3: 0
A4: CYNTHIA CABALQUINTO | B4: 0
A5: FRANCESCO CACIOPPO | B5: 0
A6: SE0KHee LEE | B6: 0
A7: SEOKHEE LEE | B7: 0
A8: Urs Zimmermann | B8: 0
A9: กชวรรณ ตรีช่วย | B9: 0
A10: กตัญญ แฟกกระโทก | B10: 0
A11: กนกพร เลียวนรเศรษฐ | B11: 0
A12: กนกวรรณ ขันพุดซา | B12: 0
A13: กนกวรรณ ชัยเครือ | B13: 0
... A923: 6TB-24060079 | B923: 0
B924: =SUBTOTAL(9,B2:B923) -> 146934.63

Sheet สรุป 67
A3: Row Labels | B3: Sum of สถานะ
A4: ANDREAS MERTENS | B4: 0
A5: ANITA CALEBAG LAPPAY | B5: 0
A6: CYNTHIA CABALQUINTO | B6: 0
A7: FRANCESCO CACIOPPO | B7: 0
A8: SE0KHee LEE | B8: 0
A9: SEOKHEE LEE | B9: 0
A10: Urs Zimmermann | B10: 0
A11: กชวรรณ ตรีช่วย | B11: 0
A12: กตัญญ แฟกกระโทก | B12: 0
A13: กนกพร เลียวนรเศรษฐ | B13: 0
A14: กนกวรรณ ขันพุดซา | B14: 0
A15: กนกวรรณ ชัยเครือ | B15: 0
... A928: Grand Total | B928: -1557.08

Sheet คืน 67
A1: Row Labels | B1: Sum of สถานะ
A2: จุฑามาศ จิตกระโทก | B2: 232.19 | C2: {=_xlfn.XLOOKUP(A2,'66 รับ'!A:A,'66 รับ'!A:A,'66 รับ'!A:A,)} -> จุฑามาศ จิตกระโทก
A3: ชนคร ขันธสม | B3: 3500 | C3: {=_xlfn.XLOOKUP(A3,'66 รับ'!A:A,'66 รับ'!A:A,'66 รับ'!A:A,)} -> ชนคร ขันธสม
A4: ชำนาญ โพธิรัชน์ | B4: 96.3 | C4: {=_xlfn.XLOOKUP(A4,'66 รับ'!A:A,'66 รับ'!A:A,'66 รับ'!A:A,)} -> ชำนาญ โพธิรัชน์
A5: ชิดชัย ประจิตร | B5: 3775 | C5: {=_xlfn.XLOOKUP(A5,'66 รับ'!A:A,'66 รับ'!A:A,'66 รับ'!A:A,)} -> ชิดชัย ประจิตร
A6: ชูศักดิ์ พัดทะเล | B6: 727.6 | C6: {=_xlfn.XLOOKUP(A6,'66 รับ'!A:A,'66 รับ'!A:A,'66 รับ'!A:A,)} -> ชูศักดิ์ พัดทะเล
A7: ณัฎรดา ทวดอาจ | B7: 2500 | C7: {=_xlfn.XLOOKUP(A7,'66 รับ'!A:A,'66 รับ'!A:A,'66 รับ'!A:A,)} -> #VALUE!
A8: ดอน วัสขุนทด | B8: 1304.06 | C8: {=_xlfn.XLOOKUP(A8,'66 รับ'!A:A,'66 รับ'!A:A,'66 รับ'!A:A,)} -> ดอน วัสขุนทด
A9: ทักษิณ ประเสริฐผล | B9: 1917.98 | C9: {=_xlfn.XLOOKUP(A9,'66 รับ'!A:A,'66 รับ'!A:A,'66 รับ'!A:A,)} -> ทักษิณ ประเสริฐผล
A10: ทันตพงษ์ ต้นสกุล | B10: 17000 | C10: {=_xlfn.XLOOKUP(A10,'66 รับ'!A:A,'66 รับ'!A:A,'66 รับ'!A:A,)} -> ทันตพงษ์ ต้นสกุล
A11: ทิวา หารประชุม | B11: 770.4 | C11: {=_xlfn.XLOOKUP(A11,'66 รับ'!A:A,'66 รับ'!A:A,'66 รับ'!A:A,)} -> ทิวา หารประชุม
A12: นพดล พึ่งเกาะ | B12: 975 | C12: {=_xlfn.XLOOKUP(A12,'66 รับ'!A:A,'66 รับ'!A:A,'66 รับ'!A:A,)} -> นพดล พึ่งเกาะ
A13: บจ.สูงเนินรวมรถ | B13: 1093.01 | C13: {=_xlfn.XLOOKUP(A13,'66 รับ'!A:A,'66 รับ'!A:A,'66 รับ'!A:A,)} -> บจ.สูงเนินรวมรถ
... A52: โอยยิ้น แซ่โต๋ว | B52: 7366.95 | C52: {=_xlfn.XLOOKUP(A52,'66 รับ'!A:A,'66 รับ'!A:A,'66 รับ'!A:A,)} -> #VALUE!
B53: 146934.63 | C53: {=_xlfn.XLOOKUP(A53,'66 รับ'!A:A,'66 รับ'!A:A,'66 รับ'!A:A,)} -> 0

Sheet Sheet6
A1: สรุปมัดจำอะไหล่ เอกสหกรุ๊ป ออโตโมบิล
A2: ยอดในงบ 67 | B2: ยอดปี 67 | C2: ยอดปี 66 | D2: ยอดขอปรับ
A3: 420899.89 | B3: 148491.71 | C3: -64242.83 | D3: =A3-B3 -> 272408.18
A6: สรุปลูกหนี้ เอกสหกรุ๊ป ออโตโมบิล
A7: ยอดในงบ 67 | B7: ยอดปี 67 | C7: ยอดขอปรับ
A8: 8882169.2 | B8: 7796435.1 | C8: =A8-B8 -> 1085734.2

Sheet มัดจำอะไหล่ 67
A1: วันที่ | B1: ขาย | C1: รายละเอียด | D1: ชื่อ | E1: ชื่อลูกค้า | F1: เลขที่ | G1: เดบิต | H1: เครดิต | I1: สถานะ | J1: ยอดคงเหลือ | K1: -418078.64
A2: 243619 | B2: รับ | C2: RVSR6701-001 | D2: นพคุณ สุขรักษาวงษ์ 3TB-23120404 | E2: นพคุณ สุขรักษาวงษ์ | F2: 3TB-23120404 | H2: 13000 | I2: =G2-H2 -> -13000 | J2: -431078.64 | K2: =+K1+G2-H2 -> -431078.64
A3: 243621 | B3: รับ | C3: RVSH6701-002 | D3: นพดล พึ่งเกาะ 5TB-23120247 | E3: นพดล พึ่งเกาะ | F3: 5TB-23120247 | G3: 975 | I3: =G3-H3 -> 975 | J3: -430103.64 | K3: =+K2+G3-H3 -> -430103.64
A4: 243621 | B4: รับ | C4: RVSS6701-001 | D4: อจลญา พิกุลแก้ว 1TB-23110015 | E4: อจลญา พิกุลแก้ว | F4: 1TB-23110015 | G4: 6700 | I4: =G4-H4 -> 6700 | J4: -423403.64 | K4: =+K3+G4-H4 -> -423403.64
A5: 243621 | B5: รับ | C5: RVSS6701-001 | D5: ไพโรจน์ ปาเกลือ 1TB-23120006 | E5: ไพโรจน์ ปาเกลือ | F5: 1TB-23120006 | G5: 3000 | I5: =G5-H5 -> 3000 | J5: -420403.64 | K5: =+K4+G5-H5 -> -420403.64
A6: 243621 | B6: รับ | C6: RVSS6701-001 | D6: มนตรี ศรีเพ็ชร์ 1TB-24010003 | E6: มนตรี ศรีเพ็ชร์ | F6: 1TB-24010003 | H6: 5000 | I6: =G6-H6 -> -5000 | J6: -425403.64 | K6: =+K5+G6-H6 -> -425403.64
A7: 243621 | B7: รับ | C7: RVSS6701-001 | D7: บจ.เค.พี.เจนเนอเรชั่น กรุ๊ป 1TB-24010004 | E7: บจ.เค.พี.เจนเนอเรชั่น กรุ๊ป | F7: 1TB-24010004 | H7: 2000 | I7: =G7-H7 -> -2000 | J7: -427403.64 | K7: =+K6+G7-H7 -> -427403.64
A8: 243622 | B8: รับ | C8: RVSN6701-001 | D8: ณัฎรดา ทวดอาจ NTB-23110001 | E8: ณัฎรดา ทวดอาจ | F8: NTB-23110001 | G8: 2500 | I8: =G8-H8 -> 2500 | J8: -424903.64 | K8: =+K7+G8-H8 -> -424903.64
A9: 243622 | B9: รับ | C9: RVSN6701-001 | D9: กฤตติกา จงเจริญ NTB-24010001 | E9: กฤตติกา จงเจริญ | F9: NTB-24010001 | H9: 3000 | I9: =G9-H9 -> -3000 | J9: -427903.64 | K9: =+K8+G9-H9 -> -427903.64
A10: 243622 | B10: รับ | C10: RVSP6701-003 | D10: นงลักษณ์ อุทัย 6TB-24010006 | E10: นงลักษณ์ อุทัย | F10: 6TB-24010006 | H10: 20000 | I10: =G10-H10 -> -20000 | J10: -447903.64 | K10: =+K9+G10-H10 -> -447903.64
A11: 243622 | B11: รับ | C11: RVSR6701-003 | D11: บดินทร์ ยางราชย์ 3TB-24010001 | E11: บดินทร์ ยางราชย์ | F11: 3TB-24010001 | H11: 224.7 | I11: =G11-H11 -> -224.7 | J11: -448128.34 | K11: =+K10+G11-H11 -> -448128.34
A12: 243622 | B12: รับ | C12: RVSR6701-003 | D12: ณัฐวุฒิ โอสระคู 3TB-24010009 | E12: ณัฐวุฒิ โอสระคู | F12: 3TB-24010009 | H12: 652.7 | I12: =G12-H12 -> -652.7 | J12: -448781.04 | K12: =+K11+G12-H12 -> -448781.04
A13: 243623 | B13: รับ | C13: RVSH6701-003 | D13: ดอน วัสขุนทด 5TB-231202160 | E13: ดอน วัสขุนทด | F13: 5TB-231202160 | G13: 1304.06 | I13: =G13-H13 -> 1304.06 | J13: -447476.98 | K13: =+K12+G13-H13 -> -447476.98
A14: 243623 | B14: รับ | C14: RVSH6701-003 | D14: ฐานุตรี หนูกระโทก 5TB-24010001 | E14: ฐานุตรี หนูกระโทก | F14: 5TB-24010001 | H14: 3860.03 | I14: =G14-H14 -> -3860.03 | J14: -451337.01 | K14: =+K13+G14-H14 -> -451337.01
A15: 243623 | B15: รับ | C15: RVSH6701-004 | D15: มานิต ก่ำพิมาย 5TB-23120272 | E15: มานิต ก่ำพิมาย | F15: 5TB-23120272 | G15: 6663.75 | I15: =G15-H15 -> 6663.75 | J15: -444673.26 | K15: =+K14+G15-H15 -> -444673.26
A16: 243623 | B16: รับ | C16: RVSH6701-004 | D16: สมศักดิ์ น้อยแสง 5TB-24010020 | E16: สมศักดิ์ น้อยแสง | F16: 5TB-24010020 | H16: 7687.95 | I16: =G16-H16 -> -7687.95 | J16: -452361.21 | K16: =+K15+G16-H16 -> -452361.21
A17: 243623 | B17: รับ | C17: RVSH6701-004 | D17: กุหลาบ ช่วยพิมาย 5TB-24010038 | E17: กุหลาบ ช่วยพิมาย | F17: 5TB-24010038 | H17: 11688.68 | I17: =G17-H17 -> -11688.68 | J17: -464049.89 | K17: =+K16+G17-H17 -> -464049.89
A18: 243623 | B18: รับ | C18: RVSP6701-004 | D18: เสกสิทธิ์ สมม่วง 6TB-24010009 | E18: เสกสิทธิ์ สมม่วง | F18: 6TB-24010009 | H18: 1800 | I18: =G18-H18 -> -1800 | J18: -465849.89 | K18: =+K17+G18-H18 -> -465849.89
A19: 243623 | B19: รับ | C19: RVSR6701-004 | D19: ประภาพรรณ เนาวเพ็ชร์ 3TB-23120392 | E19: ประภาพรรณ เนาวเพ็ชร์ | F19: 3TB-23120392 | G19: 973.7 | I19: =G19-H19 -> 973.7 | J19: -464876.19 | K19: =+K18+G19-H19 -> -464876.19
A20: 243624 | B20: รับ | C20: RVSH6701-005 | D20: วิฑูรย์ ทองทา 5TB-24010052 | E20: วิฑูรย์ ทองทา | F20: 5TB-24010052 | G20: 326 | I20: =G20-H20 -> 326 | J20: -464550.19 | K20: =+K19+G20-H20 -> -464550.19
A21: 243624 | B21: รับ | C21: RVSH6701-005 | D21: กุหลาบ ช่วยพิมาย 5TB-24010038 | E21: กุหลาบ ช่วยพิมาย | F21: 5TB-24010038 | G21: 11688.68 | I21: =G21-H21 -> 11688.68 | J21: -452861.51 | K21: =+K20+G21-H21 -> -452861.51
A22: 243624 | B22: รับ | C22: RVSH6701-005 | D22: วิฑูรย์ ทองทา 5TB-24010053 | E22: วิฑูรย์ ทองทา | F22: 5TB-24010053 | H22: 326.35 | I22: =G22-H22 -> -326.35 | J22: -453187.86 | K22: =+K21+G22-H22 -> -453187.86
A23: 243624 | B23: รับ | C23: RVSH6701-005 | D23: วิฑูรย์ ทองทา 5TB-24010052 | E23: วิฑูรย์ ทองทา | F23: 5TB-24010052 | H23: 326 | I23: =G23-H23 -> -326 | J23: -453513.86 | K23: =+K22+G23-H23 -> -453513.86
A24: 243624 | B24: รับ | C24: RVSR6701-005 | D24: หจก.วีระพลออโต้เซอร์วิส 3TB-24010027 | E24: หจก.วีระพลออโต้เซอร์วิส | F24: 3TB-24010027 | H24: 4700 | I24: =G24-H24 -> -4700 | J24: -458213.86 | K24: =+K23+G24-H24 -> -458213.86
A25: 243624 | B25: รับ | C25: RVSR6701-005 | D25: อดิศักดิ์ แสงนาค 3TB-24010037 | E25: อดิศักดิ์ แสงนาค | F25: 3TB-24010037 | H25: 4400 | I25: =G25-H25 -> -4400 | J25: -462613.86 | K25: =+K24+G25-H25 -> -462613.86
A26: 243624 | B26: รับ | C26: RVSR6701-005 | D26: จักรกฤษณ์ กิจสมชีพ 3TB-24010038 | E26: จักรกฤษณ์ กิจสมชีพ | F26: 3TB-24010038 | H26: 492.2 | I26: =G26-H26 -> -492.2 | J26: -463106.06 | K26: =+K25+G26-H26 -> -463106.06
A27: 243624 | B27: รับ | C27: RVSR6701-005 | D27: อินทิชา บุญชิต 3TB-24010041 | E27: อินทิชา บุญชิต | F27: 3TB-24010041 | H27: 144.45 | I27: =G27-H27 -> -144.45 | J27: -463250.51 | K27: =+K26+G27-H27 -> -463250.51
A28: 243624 | B28: รับ | C28: RVSR6701-006 | D28: บดินทร์ ยางราชย์ 3TB-24010001 | E28: บดินทร์ ยางราชย์ | F28: 3TB-24010001 | G28: 224.7 | I28: =G28-H28 -> 224.7 | J28: -463025.81 | K28: =+K27+G28-H28 -> -463025.81
A29: 243625 | B29: รับ | C29: RVSH6701-006 | D29: ชิดชัย ประจิตร 5TB-23120273 | E29: ชิดชัย ประจิตร | F29: 5TB-23120273 | G29: 1885 | I29: =G29-H29 -> 1885 | J29: -461140.81 | K29: =+K28+G29-H29 -> -461140.81
A30: 243625 | B30: รับ | C30: RVSH6701-006 | D30: ชิดชัย ประจิตร 5TB-23120275 | E30: ชิดชัย ประจิตร | F30: 5TB-23120275 | G30: 1890 | I30: =G30-H30 -> 1890 | J30: -459250.81 | K30: =+K29+G30-H30 -> -459250.81
A31: 243625 | B31: รับ | C31: RVSP6701-006 | D31: อาคม เกิดในแก้ว 6TB-24010028 | E31: อาคม เกิดในแก้ว | F31: 6TB-24010028 | H31: 1872.5 | I31: =G31-H31 -> -1872.5 | J31: -461123.31 | K31: =+K30+G31-H31 -> -461123.31
A32: 243625 | B32: รับ | C32: RVSR6701-007 | D32: รัตนาภรณ์ รัตนเพช 3TB-23120411 | E32: รัตนาภรณ์ รัตนเพช | F32: 3TB-23120411 | G32: 3000 | I32: =G32-H32 -> 3000 | J32: -458123.31 | K32: =+K31+G32-H32 -> -458123.31
A33: 243627 | B33: รับ | C33: RVSH6701-007 | D33: ประชา มุ่งยอดกลาง 5TB-23110348 | E33: ประชา มุ่งยอดกลาง | F33: 5TB-23110348 | G33: 347.75 | I33: =G33-H33 -> 347.75 | J33: -457775.56 | K33: =+K32+G33-H33 -> -457775.56
A34: 243627 | B34: รับ | C34: RVSH6701-007 | D34: ฐานุตรี หนุกระโทก 5TB-24010007 | E34: ฐานุตรี หนูกระโทก | F34: 5TB-24010007 | G34: 3860.03 | I34: =G34-H34 -> 3860.03 | J34: -453915.53 | K34: =+K33+G34-H34 -> -453915.53
A35: 243627 | B35: รับ | C35: RVSH6701-007 | D35: ธนาเทพ ศรียางนอก (ร้านเทพทอง) 5TB-24010082 | E35: ธนาเทพ ศรียางนอก (ร้านเทพทอง) | F35: 5TB-24010082 | H35: 3222 | I35: =G35-H35 -> -3222 | J35: -457137.53 | K35: =+K34+G35-H35 -> -457137.53
A36: 243627 | B36: รับ | C36: RVSH6701-007 | D36: เศรษฐวฒน์ แย้มทะเล 5TB-24010078 | E36: เศรษฐวฒน์ แย้มทะเล | F36: 5TB-24010078 | H36: 5770 | I36: =G36-H36 -> -5770 | J36: -462907.53 | K36: =+K35+G36-H36 -> -462907.53
A37: 243627 | B37: รับ | C37: RVSH6701-007 | D37: เกียรติศักดิ์ รัตนะวงศะวัต 5TB-24010077 | E37: เกียรติศักดิ์ รัตนะวงศะวัต | F37: 5TB-24010077 | H37: 321 | I37: =G37-H37 -> -321 | J37: -463228.53 | K37: =+K36+G37-H37 -> -463228.53
A38: 243627 | B38: รับ | C38: RVSR6701-008 | D38: หจก.วีระพลออโต้เซอร์วิส 3TB-24010027 | E38: หจก.วีระพลออโต้เซอร์วิส | F38: 3TB-24010027 | G38: 4700 | I38: =G38-H38 -> 4700 | J38: -458528.53 | K38: =+K37+G38-H38 -> -458528.53
A39: 243627 | B39: รับ | C39: RVSR6701-008 | D39: สุเทพ ไกรกลาง 3TB-24010111 | E39: สุเทพ ไกรกลาง | F39: 3TB-24010111 | H39: 13524.8 | I39: =G39-H39 -> -13524.8 | J39: -472053.33 | K39: =+K38+G39-H39 -> -472053.33
A40: 243627 | B40: รับ | C40: RVSR6701-008 | D40: พิสมร แก้วสำราญ 3TB-24010119 | E40: พิสมร แก้วสำราญ | F40: 3TB-24010119 | H40: 9000 | I40: =G40-H40 -> -9000 | J40: -481053.33 | K40: =+K39+G40-H40 -> -481053.33
...

Sheet สรุป 66
A3: Row Labels | B3: Sum of สถานะ
A4: ISD MOHAMED | B4: 0 | D4: 3000 | E4: รับปี 65
A5: Karlmartin Horat | B5: 0 | D5: 7000
A6: Kim | B6: 0
A7: MICHAEL DYKES | B7: 0 | D7: 8150 | E7: มีคืน ไม่มีรับ
A8: TIN MAUNG AYE. | B8: 0
A9: กชกร ฝายอุประ | B9: 0
A10: กชพรพรรณ โนนขุนทด | B10: 0
A11: กนกพร จงกลาง | B11: 0
A12: กนกอร นันทะเสน | B12: 0
A13: กมลชนก ปุราสะเก | B13: 0
A14: กมลทิพย์ คุ้มเรือน | B14: 0
A15: กมลทิพย์ มะแม้น | B15: 0
A16: กมลวรรณ์ อองเดรท์ | B16: 0
A17: กรกนก จิตร์อารี | B17: 0
A18: กรกาญจน์ จีรพัฒนพงษ์ | B18: 0
A19: กรณิการ์ พิมพา | B19: 0
... A1162: โอฬาร บุญจันทร์ | B1162: 0
A1163: (blank)
A1164: มิเนอเรกซ์ จำกัด | B1164: 0
A1165: Grand Total | B1165: -38955.63

Sheet Sheet3
A3: Row Labels | B3: Sum of สถานะ
A4: ISD MOHAMED | B4: 0 | D4: 3000 | E4: รับปี 65
A5: Karlmartin Horat | B5: 0 | D5: 7000
A6: Kim | B6: 0
A7: MICHAEL DYKES | B7: 0 | D7: 8150 | E7: มีคืน ไม่มีรับ
A8: TIN MAUNG AYE. | B8: 0
A9: กชกร ฝายอุประ | B9: 0
A10: กชพรพรรณ โนนขุนทด | B10: 0
A11: กนกพร จงกลาง | B11: 0
A12: กนกอร นันทะเสน | B12: 0
A13: กมลชนก ปุราสะเก | B13: 0
A14: กมลทิพย์ คุ้มเรือน | B14: 0
A15: กมลทิพย์ มะแม้น | B15: 0
A16: กมลวรรณ์ อองเดรท์ | B16: 0
A17: กรกนก จิตร์อารี | B17: 0
A18: กรกาญจน์ จีรพัฒนพงษ์ | B18: 0
A19: กรณิการ์ พิมพา | B19: 0
... A1038: มิเนอเรกซ์ จำกัด | B1038: 0
A1039: Grand Total | B1039: =SUM(B4:B1038) -> -37297.43

Sheet Sheet2
A3: Row Labels | B3: Sum of สถานะ
A4: กรภัทร์ คงนาวัง | B4: -1000
A5: กฤษณ์ นาคสูงเนิน | B5: 7000
A6: กันญาวีษ์ ดิษพงษา | B6: 3000
A7: กัลยาณัฏฐ์ เที่ยงจันทึก | B7: 8150
A8: เขมณัฏฐ์ วงศ์มนต์เทวัญ | B8: -6000
A9: คณิศร์ บรรลุสิน | B9: 10050.51
A10: จันทกานติ เพ็ชรเขียนขจร | B10: -449.4
A11: จารุวัฒน์ ประจีณวงศ์วุฒิ | B11: -609.9
A12: จุฑามาศ จิตกระโทก | B12: -232.19
A13: จุไรวรรณ ลือพงศ์พัฒนะ | B13: 117.7
A14: ชฎิลดา ดั้งดวงศศิธร | B14: -6000
A15: ชนคร ขันธสม | B15: -3500
... A138: Grand Total | B138: -37297.43

Sheet 66 รับ
A1: กรภัทร์ คงนาวัง | B1: -1000 | C1: #N/A | D1: 3TB-23030500 | E1: 243344
A2: เขมณัฏฐ์ วงศ์มนต์เทวัญ | B2: -6000 | C2: #N/A | D2: 5TB-23060371 | E2: 243429
A3: จันทกานติ เพ็ชรเขียนขจร | B3: -449.4 | C3: #N/A | D3: 6TB-23050035 | E3: 243383
A4: จารุวัฒน์ ประจีณวงศ์วุฒิ | B4: -609.9 | C4: #N/A | D4: 5TB-23090255 | E4: 243516
A5: จุฑามาศ จิตกระโทก | B5: -232.19 | C5: จุฑามาศ จิตกระโทก | D5: 5TB-23110302 | E5: 243582
A6: ชฎิลดา ดั้งดวงศศิธร | B6: -6000 | C6: #N/A | D6: NTB-23070002 | E6: 243445
A7: ชนคร ขันธสม | B7: -3500 | C7: ชนคร ขันธสม | D7: 6TB-23120147 | E7: 243614
A8: ชำนาญ โพธิรัชน์ | B8: -96.3 | C8: ชำนาญ โพธิรัชน์ | D8: 3TB-23120290 | E8: 243609
A9: ชำนาญ รื่นจิตต์ | B9: -500 | C9: #N/A | D9: 6TB-23010026 | E9: 243262
A10: ชิดชัย ประจิตร | B10: -3775 | C10: ชิดชัย ประจิตร | D10: 5TB-23120273 | E10: 243613
A11: ชูศักดิ์ พัดทะเล | B11: -727.6 | C11: ชูศักดิ์ พัดทะเล | D11: 5TB-23120308 | E11: 243615
A12: ฐาณัชชา รายณะสุข | B12: -2000 | C12: #N/A | D12: 5TB23060225 | E12: 243420
A13: ณัฎธิณี พึ้งน้อย | B13: -732.95 | C13: #N/A | D13: 6TB-23120060 | E13: 243599
A14: ณัฏธิณี พึ้งน้อย | B14: -941.6 | C14: #N/A | D14: 6TB-23120059 | E14: 243597
A15: ณัฏรดา ทวดอาจ | B15: -2500 | C15: #N/A | D15: NTB-23110001 | E15: 243574
A16: ณัฐพล หอมกลิ่น | B16: -7000 | C16: #N/A | D16: 1TB-23070051 | E16: 243447
A17: ณัฐรดา แสนคุ้ม | B17: -6000 | C17: #N/A | D17: NTB-23090001 | E17: 243498
A18: ณัฐวุฒิ ขันธปรีชา | B18: -754.35 | C18: #N/A | D18: 5TB-2301410 | E18: 243284
A19: ดอน วัสขุนทด | B19: -1304.06 | C19: ดอน วัสขุนทด | D19: 5TB-23120160 | E19: 243602
A20: ตุ้ย บุญเรือง | B20: -2500 | C20: #N/A | D20: 1TB-23100005 | E20: 243539
A21: ถิรดา ณัฐศาพงศ์ | B21: -3000 | C21: #N/A | D21: 1TB-23050011 | E21: 243378
A22: ทักษิณ ประเสริฐผล | B22: -1917.98 | C22: ทักษิณ ประเสริฐผล | D22: 3TB-23120412 | E22: 243616
A23: ทันตพงษ์ ต้นสกุล | B23: -17000 | C23: ทันตพงษ์ ต้นสกุล | D23: 6TB-23100085 | E23: 243544
A24: ทิวา หารประชุม | B24: -770.4 | C24: ทิวา หารประชุม | D24: 5TB-23120343 | E24: 243617
A25: ธันยาภัทร์ ริยะสารชัยรัฐ | B25: -4000 | C25: #N/A | D25: NTB-23060003 | E25: 243434
A26: นพดล พึ่งเกาะ | B26: -975 | C26: นพดล พึ่งเกาะ | D26: 5TB-23120247 | E26: 243610
A27: นุชนาถ เดือนขาว | B27: -3000 | C27: #N/A | D27: 1TB-23060050 | E27: 243424
A28: บจ.สำนักงานกฎหมายรัฐนนท์ | B28: -8000 | C28: #N/A | D28: NTB-23080002 | E28: 243467
A29: บจ.สูงเนินรวมรถ | B29: -1093.01 | C29: บจ.สูงเนินรวมรถ | D29: 3TB-23090317 | E29: 243519
A30: บริษัท เคโอเคโอ อินเตอร์เทรค จำกัด | B30: -11660 | C30: #N/A | D30: 5TB-23080093 | E30: 243474
A31: ประชา มุ่งยอดกลาง | B31: -347.75 | C31: #N/A | D31: 5TB-23110348 | E31: 243585
A32: ประชา เล้าเจริญพานิชย์ | B32: -5240.75 | C32: ประชา เล้าเจริญพานิชย์ | D32: 3TB-23050404 | E32: 243398
A33: ประภาพรรณ เนาวเพ็ชร์ | B33: -973.7 | C33: ประภาพรรณ เนาวเพ็ชร์ | D33: 3TB-23120392 | E33: 243615
A34: ปราถนา ทิพย์อาศน์ | B34: -6300 | C34: ปราถนา ทิพย์อาศน์ | D34: 1TB-23110013 | E34: 243566
A35: ผกามาศ ไกลกลาง | B35: -5024.99 | C35: #N/A | D35: 062/3070 | E35: 243336
A36: ผกามาส จันทรวงศา | B36: -398.84 | C36: #N/A | D36: 062/3066 | E36: 243336
A37: พงศ์ธร โสภณธรรมกิจ | B37: -8321.75 | C37: #N/A | D37: 3TB-22120182 | E37: 243260
A38: พบชัย พานปรุ | B38: -1000 | C38: #N/A | D38: 5TB23060226 | E38: 243420
A39: พรนภา ทิพโคกกรวด | B39: -2000 | C39: #N/A | D39: 5TB-23060212 | E39: 243418
A40: พะยุง เขนสันเทียะ | B40: -1470 | C40: พะยุง เขนสันเทียะ | D40: 3TB-23040411 | E40: 243369
...

Sheet Sheet4
A1: บริษัท เอกสหกรุ๊ป ออโตโมบิล จำกัด
A2: ณ วันที่ 31 ธันวาคม 2567
A3: ลำดับ | B3: ชื่อลูกค้า | C3: เลขที่มัดจำ | D3: วันที่ | E3: จำนวนเงิน
A4: 1 | B4: ผกามาส จันทรวงศา | C4: 062/3066 | D4: 243336 | E4: -398.84
A5: 2 | B5: ผกามาศ ไกลกลาง | C5: 062/3070 | D5: 243336 | E5: -5024.99
A6: 3 | B6: สมคิด อดูลปรัชญากร | C6: 062-3093 | D6: 243475 | E6: -85.6
A7: 4 | B7: ถิรดา ณัฐศาพงศ์ | C7: 1TB-23050011 | D7: 243378 | E7: -3000 | F7: 1TM-23050002
A8: 5 | B8: นุชนาถ เดือนขาว | C8: 1TB-23060050 | D8: 243424 | E8: -3000 | F8: 1TM-23060003
A9: 6 | B9: สุริยันต์ มีปากดี | C9: 1TB-23070050 | D9: 243447 | E9: -3000 | F9: 1TM-23070001
A10: 7 | B10: ณัฐพล หอมกลิ่น | C10: 1TB-23070051 | D10: 243447 | E10: -7000 | F10: 1TM-23070002
A11: 8 | B11: อุษา สุขมณี | C11: 1TB-23070083 | D11: 243461 | E11: -1000 | F11: 1TM-23070003
A12: 9 | B12: ตุ้ย บุญเรือง | C12: 1TB-23100005 | D12: 243539 | E12: -2500 | F12: 1TM-23100001
A13: 10 | B13: โอภาส ปานสารี | C13: 1TB-23100023 | D13: 243558 | E13: -1000 | F13: 1TM-23100003
A14: 11 | B14: กรภัทร์ คงนาวัง | C14: 3TB-23030500 | D14: 243344 | E14: -1000 | F14: 3TM-23030067
A15: 12 | B15: ภัสร์สุชาสินี อัครพิชชานนท์ | C15: 3TB-23100300 | D15: 243547 | E15: -3000 | F15: 3TM-23100034
A16: 13 | B16: ณัฐวุฒิ ขันธปรีชา | C16: 5TB-23010410 | D16: 243284 | E16: -754.35 | F16: 5TM-23010049
A17: 14 | B17: วัลลภ ภาษี | C17: 5TB-23020280 | D17: 243306 | E17: -979.05 | F17: 5TM-23020038
A18: 15 | B18: ฐาณัชชา รายณะสุข | C18: 5TB-23060225 | D18: 243420 | E18: -2000 | F18: 5TM-23060035
... A21: 18 | B21: สุรชัย ไตรภูธร | C21: NTB-23060001 | D21: 243418 | E21: -2000 | F21: NTM-23060001
A22: 19 | B22: ธันยาภัทร์ ริยะสารชัยรัฐ | C22: NTB-23060003 | D22: 243434 | E22: -4000
A23: 20 | B23: ชฎิลดา ดั้งดวงศศิธร | C23: NTB-23070002 | D23: 243445 | E23: -6000
A24: 21 | B24: ศรารัตน์ ชาลี | C24: NTB-23080001 | D24: 243467 | E24: -5000 | F24: NTM-23080001
A25: 22 | B25: บจ.สำนักงานกฎหมายรัฐนนท์ | C25: NTB-23080002 | D25: 243467 | E25: 3000 | F25: NTM-23080002
A26: 23 | B26: ณัฐรดา แสนคุ้ม | C26: NTB-23090001 | D26: 243498 | E26: -6000 | F26: NTM-23090001
A27: 24 | B27: วัจน์กร ดาศรี | C27: NTB-23090002 | D27: 243526 | E27: -1000 | F27: NTM-23090002
A28: 25 | B28: ณัฏรดา ทวดอาจ | C28: NTB-23110001 | D28: 243574 | E28: -2500 | F28: NTM-23110001
A29: ยอดรวม | E29: =SUM(E4:E28) -> -64242.83
A33: 6 | B33: เยาวลักษณ์ หงษ์นคร | C33: 1TB-23070001 | D33: 243436 | E33: -15345.43
A34: 10 | B34: สิริรัตน์ กุรัมย์ | C34: 1TB-23090023 | D34: 243532 | E34: -16400.96

Sheet Sheet7
A1: กฤษณ์ นาคสูงเนิน | B1: 7000
A2: กันญาวีษ์ ดิษพงษา | B2: 3000
A3: กัลยาณัฏฐ์ เที่ยงจันทึก | B3: 8150
A4: คณิศร์ บรรลุสิน | B4: 10050.51
A5: จุไรวรรณ ลือพงศ์พัฒนะ | B5: 117.7
A6: ชัยณรงค์ ไกรกลาง | B6: 3000
A7: เชาวลิต สินิทธ์กุล | B7: 3430.69
A8: ณัฎธิณี พึ้งงน้อย | B8: 1674.55
A9: ณัฐชนน สมานจารุวรรณ | B9: 246.1
A10: ทัยชนก ไชยแสง | B10: 3000
A11: ทิพากร พรมยกบัตร์ | B11: 112.35
A12: ทีปกรณ์ วิศรุตวาณิชย์ | B12: 1320.12
... A52: อิศวัฒน์ อิธินันท์วัธนากูร | B52: 2200

Sheet ปกมัดจำอะไหล่
G2: N.........
B8: บริษัท เอกสหกรุ๊ป ออโตโมบิล จำกัด
B9: ณ 31 ธันวาคม 2567
B12: รหัสบัญชี | C12: ชื่อบัญชี | F12: ยอดตามงบ
B14: 2205-04-00 | C14: เงินรับมัดจำ-ค่าอะไหล่และบริการ | F14: -148491.71
B26: ยืนยันยอดที่ถูกต้อง ณ 31 ธันวาคม 2567 | F26: =F14-F15 -> -148491.71
B30: ผู้จัดทำ | F30: ผู้สอบทาน
B32: วันที่จัดทำ | F32: วันที่สอบทาน

Sheet N 66
A1: วันที่ | B1: สมุด | C1: ใบสำคัญ | D1: คำอธิบาย | E1: เลขที่เอกสาร | F1: ชื่อลูกค้า | G1: เดบิต | H1: เครดิต | I1: สถานะ | J1: ยอดคงเหลือ
A2: 2205-04-00 | C2: เงินรับมัดจำ-ค่าอะไหล่และบริการ | J2: -379113.76
A3: 243257 | B3: รับ | C3: RVSH6601-001 | D3: นาตยา แก้วไทย 5TB-23010003 | E3: 5TB-23010003 | F3: นาตยา แก้วไทย | H3: 881.68 | I3: =G3-H3 -> -881.68 | J3: -379995.44 | K3: =+J2+G3-H3 -> -379995.44
A4: 243257 | B4: รับ | C4: RVSH6601-001 | D4: ร้านยาวการยาง 5TB-23010013 | E4: 5TB-23010013 | F4: ร้านยาวการยาง | H4: 251.45 | I4: =G4-H4 -> -251.45 | J4: -380246.89 | K4: =+J3+G4-H4 -> -380246.89
A5: 243257 | B5: รับ | C5: RVSH6601-001 | D5: ไมตรี หนูเจริญกูล 5TB-23010015 | E5: 5TB-23010015 | F5: ไมตรี หนูเจริญกูล | H5: 731.88 | I5: =G5-H5 -> -731.88 | J5: -380978.77 | K5: =+J4+G5-H5 -> -380978.77
A6: 243258 | B6: รับ | C6: RVSH6601-003 | D6: สิทธิชัย จันทร์เทศ 5TB-22120244 | E6: 5TB-22120244 | F6: สิทธิชัย จันทร์เทศ | G6: 47000 | I6: =G6-H6 -> 47000 | J6: -333978.77 | K6: =+J5+G6-H6 -> -333978.77
A7: 243258 | B7: รับ | C7: RVSH6601-003 | D7: น้ำฝน โชติกลาง 5TB-23010027 | E7: 5TB-23010027 | F7: น้ำฝน โชติกลาง | H7: 881.68 | I7: =G7-H7 -> -881.68 | J7: -334860.45 | K7: =+J6+G7-H7 -> -334860.45
A8: 243258 | B8: รับ | C8: RVSR6601-002 | D8: อู่พีเอ็น เซอร์วิส 3TB-23010005 | E8: 3TB-23010005 | F8: อู่พีเอ็น เซอร์วิส | H8: 1600 | I8: =G8-H8 -> -1600 | J8: -336460.45 | K8: =+J7+G8-H8 -> -336460.45
A9: 243258 | B9: รับ | C9: RVSR6601-002 | D9: อู่สินเจริญ 3TB-23010014 | E9: 3TB-23010014 | F9: อู่สินเจริญ | H9: 5300 | I9: =G9-H9 -> -5300 | J9: -341760.45 | K9: =+J8+G9-H9 -> -341760.45
A10: 243258 | B10: รับ | C10: RVSR6601-003 | D10: หอมหวล วันนา 3TB-22120339 | E10: 3TB-22120339 | F10: หอมหวล วันนา | G10: 812.13 | I10: =G10-H10 -> 812.13 | J10: -340948.32 | K10: =+J9+G10-H10 -> -340948.32
A11: 243259 | B11: รับ | C11: RS6601-007 | D11: รับชำระหนี้ บมจ. นวกิจประกันภัย | E11: นวกิจประกันภัย | F11: รับชำระหนี้ บมจ. | G11: 1000 | I11: =G11-H11 -> 1000 | J11: -339948.32 | K11: =+J10+G11-H11 -> -339948.32
A12: 243259 | B12: รับ | C12: RVSH6601-002 | D12: ภูริวัจน์ ชัยศิริสุภานนท์ 5TB-23010021 | E12: 5TB-23010021 | F12: ภูริวัจน์ ชัยศิริสุภานนท์ | H12: 40956 | I12: =G12-H12 -> -40956 | J12: -380904.32 | K12: =+J11+G12-H12 -> -380904.32
A13: 243259 | B13: รับ | C13: RVSP6601-003 | D13: สโรชา เหล่าศิริรัตน์ 6TB-23010008 | E13: 6TB-23010008 | F13: สโรชา เหล่าศิริรัตน์ | H13: 807.85 | I13: =G13-H13 -> -807.85 | J13: -381712.17 | K13: =+J12+G13-H13 -> -381712.17
A14: 243259 | B14: รับ | C14: RVSR6601-004 | D14: อนุวัฒน์ สังฆะงาม 3TB-23010018 | E14: 3TB-23010018 | F14: อนุวัฒน์ สังฆะงาม | H14: 69.55 | I14: =G14-H14 -> -69.55 | J14: -381781.72 | K14: =+J13+G14-H14 -> -381781.72
A15: 243259 | B15: รับ | C15: RVSR6601-004 | D15: พัทธนันท์ ปุณญพร 3TB-23010019 | E15: 3TB-23010019 | F15: พัทธนันท์ ปุณญพร | H15: 334 | I15: =G15-H15 -> -334 | J15: -382115.72 | K15: =+J14+G15-H15 -> -382115.72
A16: 243259 | B16: รับ | C16: RVSR6601-004 | D16: โสภณ แก้วยงกฎ 3TB-23010027 | E16: 3TB-23010027 | F16: โสภณ แก้วยงกฎ | H16: 264.29 | I16: =G16-H16 -> -264.29 | J16: -382380.01 | K16: =+J15+G16-H16 -> -382380.01
A17: 243259 | B17: รับ | C17: RVSR6601-004 | D17: สมชาย กองกุล 3TB-23010029 | E17: 3TB-23010029 | F17: สมชาย กองกุล | H17: 674.1 | I17: =G17-H17 -> -674.1 | J17: -383054.11 | K17: =+J16+G17-H17 -> -383054.11
A18: 243260 | B18: รับ | C18: RVSH6601-005 | D18: ชญาดา กัลยาณรุจ 5TB-23010038 | E18: 5TB-23010038 | F18: ชญาดา กัลยาณรุจ | H18: 881.68 | I18: =G18-H18 -> -881.68 | J18: -383935.79 | K18: =+J17+G18-H18 -> -383935.79
A19: 243260 | B19: รับ | C19: RVSH6601-006 | D19: ร้านยาวการยาง 5TB-23010013 | E19: 5TB-23010013 | F19: ร้านยาวการยาง | G19: 251.45 | I19: =G19-H19 -> 251.45 | J19: -383684.34 | K19: =+J18+G19-H19 -> -383684.34
A20: 243260 | B20: รับ | C20: RVSR6601-006 | D20: หทัยพัชร มหรรณพนที 3TB-22110308 | E20: 3TB-22110308 | F20: หทัยพัชร มหรรณพนที | G20: 3288.65 | I20: =G20-H20 -> 3288.65 | J20: -380395.69 | K20: =+J19+G20-H20 -> -380395.69
A21: 243260 | B21: รับ | C21: RVSR6601-006 | D21: พงศ์ธร โสภณธรรมกิจ 3TB-22120182 | E21: 3TB-22120182 | F21: พงศ์ธร โสภณธรรมกิจ | G21: 2648.25 | I21: =G21-H21 -> 2648.25 | J21: -377747.44 | K21: =+J20+G21-H21 -> -377747.44
A22: 243261 | B22: รับ | C22: RVSP6601-006 | D22: ประจวบ จงโปร่งกลาง 6TB-23010024 | E22: 6TB-23010024 | F22: ประจวบ จงโปร่งกลาง | H22: 2000 | I22: =G22-H22 -> -2000 | J22: -379747.44 | K22: =+J21+G22-H22 -> -379747.44
A23: 243261 | B23: รับ | C23: RVSR6601-008 | D23: ธาวิน หอมศักดิ์มงคล 3TB-22120228 | E23: 3TB-22120228 | F23: ธาวิน หอมศักดิ์มงคล | G23: 14750.75 | I23: =G23-H23 -> 14750.75 | J23: -364996.69 | K23: =+J22+G23-H23 -> -364996.69
A24: 243261 | B24: รับ | C24: RVSR6601-008 | D24: อนุวัฒน์ สังฆะงาม 3TB-23010018 | E24: 3TB-23010018 | F24: อนุวัฒน์ สังฆะงาม | G24: 69.55 | I24: =G24-H24 -> 69.55 | J24: -364927.14 | K24: =+J23+G24-H24 -> -364927.14
A25: 243261 | B25: รับ | C25: RVSR6601-008 | D25: อู่พีเอ็น เซอร์วิส 3TB-23010005 | E25: 3TB-23010005 | F25: อู่พีเอ็น เซอร์วิส | G25: 1600 | I25: =G25-H25 -> 1600 | J25: -363327.14 | K25: =+J24+G25-H25 -> -363327.14
A26: 243261 | B26: รับ | C26: RVSR6601-008 | D26: อู่สินเจริญ 3TB-23010014 | E26: 3TB-23010014 | F26: อู่สินเจริญ | G26: 5300 | I26: =G26-H26 -> 5300 | J26: -358027.14 | K26: =+J25+G26-H26 -> -358027.14
A27: 243262 | B27: รับ | C27: RVSP6601-007 | D27: ชำนาญ รื่นจิตต์ 6TB-23010026 | E27: 6TB-23010026 | F27: ชำนาญ รื่นจิตต์ | H27: 500 | I27: =G27-H27 -> -500 | J27: -358527.14 | K27: =+J26+G27-H27 -> -358527.14
A28: 243262 | B28: รับ | C28: RVSP6601-007 | D28: มณีวรรณ วังคะฮาตแสนสุข 6TB-22120041 | E28: 6TB-22120041 | F28: มณีวรรณ วังคะฮาตแสนสุข | G28: 1600 | I28: =G28-H28 -> 1600 | J28: -356927.14 | K28: =+J27+G28-H28 -> -356927.14
A29: 243262 | B29: รับ | C29: RVSP6601-007 | D29: กันญาวีษ์ ดิษพงษา 6TB-22120163 | E29: 6TB-22120163 | F29: กันญาวีษ์ ดิษพงษา | G29: 3000 | I29: =G29-H29 -> 3000 | J29: -353927.14 | K29: =+J28+G29-H29 -> -353927.14
A30: 243263 | B30: รับ | C30: RVSP6601-009 | D30: พงษ์ทวี มี่แคน 6TB-23010036 | E30: 6TB-23010036 | F30: พงษ์ทวี มี่แคน | H30: 4400 | I30: =G30-H30 -> -4400 | J30: -358327.14 | K30: =+J29+G30-H30 -> -358327.14
A31: 243263 | B31: รับ | C31: RVSR6601-009 | D31: จุมพฏ ประสงค์ 3TB-23010105 | E31: 3TB-23010105 | F31: จุมพฏ ประสงค์ | H31: 3300 | I31: =G31-H31 -> -3300 | J31: -361627.14 | K31: =+J30+G31-H31 -> -361627.14
A32: 243263 | B32: รับ | C32: RVSR6601-010 | D32: หจก.รถขุด 2002 3TB-22120358 | E32: 3TB-22120358 | F32: หจก.รถขุด 2002 | G32: 888.1 | I32: =G32-H32 -> 888.1 | J32: -360739.04 | K32: =+J31+G32-H32 -> -360739.04
A33: 243263 | B33: รับ | C33: RVSR6601-010 | D33: ปริยาพร นิลปานะ 3TB-23010116 | E33: 3TB-23010116 | F33: ปริยาพร นิลปานะ | H33: 1059.3 | I33: =G33-H33 -> -1059.3 | J33: -361798.34 | K33: =+J32+G33-H33 -> -361798.34
A34: 243264 | B34: รับ | C34: RVSH6601-009 | D34: นาตยา แก้วไทย 5TB-23010003 | E34: 5TB-23010003 | F34: นาตยา แก้วไทย | G34: 881.68 | I34: =G34-H34 -> 881.68 | J34: -360916.66 | K34: =+J33+G34-H34 -> -360916.66
A35: 243264 | B35: รับ | C35: RVSP6601-011 | D35: สโรชา เหล่าศิริรัตน์ 6TB-23010008 | E35: 6TB-23010008 | F35: สโรชา เหล่าศิริรัตน์ | G35: 807.85 | I35: =G35-H35 -> 807.85 | J35: -360108.81 | K35: =+J34+G35-H35 -> -360108.81
A36: 243264 | B36: รับ | C36: RVSP6601-012 | D36: นริศ ฤทธิชัยฤกษ์ 6TB-23010043 | E36: 6TB-23010043 | F36: นริศ ฤทธิชัยฤกษ์ | H36: 90 | I36: =G36-H36 -> -90 | J36: -360198.81 | K36: =+J35+G36-H36 -> -360198.81
A37: 243264 | B37: รับ | C37: RVSR6601-011 | D37: ธนากร วิมลศิลป์ 3TB-22120346 | E37: 3TB-22120346 | F37: ธนากร วิมลศิลป์ | G37: 4879.2 | I37: =G37-H37 -> 4879.2 | J37: -355319.61 | K37: =+J36+G37-H37 -> -355319.61
A38: 243264 | B38: รับ | C38: RVSR6601-011 | D38: ทีปกรณ์ วิศรุตวาณิชย์ 3TB-22110424 | E38: 3TB-22110424 | F38: ทีปกรณ์ วิศรุตวาณิชย์ | G38: 1320.12 | I38: =G38-H38 -> 1320.12 | J38: -353999.49 | K38: =+J37+G38-H38 -> -353999.49
A39: 243264 | B39: รับ | C39: RVSR6601-011 | D39: สุรีย์ จุลสิขรี 3TB-22120252 | E39: 3TB-22120252 | F39: สุรีย์ จุลสิขรี | G39: 3215.35 | I39: =G39-H39 -> 3215.35 | J39: -350784.14 | K39: =+J38+G39-H39 -> -350784.14
A40: 243264 | B40: รับ | C40: RVSR6601-011 | D40: โสภณ แก้วยงกฎ 3TB-23010027 | E40: 3TB-23010027 | F40: โสภณ แก้วยงกฎ | G40: 264.29 | I40: =G40-H40 -> 264.29 | J40: -350519.85 | K40: =+J39+G40-H40 -> -350519.85
...

Sheet Sheet1
A1: นพคุณ สุขรักษาวงษ์ 3TB-23120404 | D1: =IF(ISNUMBER(LEFT(A1,1)*1),LEFT(A1,FIND(" ",A1)-1),RIGHT(A1,LEN(A1)-FIND("@",SUBSTITUTE(A1," ","@",LEN(A1)-LEN(SUBSTITUTE(A1," ","")))))) -> 3TB-23120404 | G1: =TRIM(SUBSTITUTE(A1, D1, "")) -> นพคุณ สุขรักษาวงษ์
A2: นพดล พึ่งเกาะ 5TB-23120247 | D2: =IF(ISNUMBER(LEFT(A2,1)*1),LEFT(A2,FIND(" ",A2)-1),RIGHT(A2,LEN(A2)-FIND("@",SUBSTITUTE(A2," ","@",LEN(A2)-LEN(SUBSTITUTE(A2," ","")))))) -> 5TB-23120247 | G2: =TRIM(SUBSTITUTE(A2, D2, "")) -> นพดล พึ่งเกาะ
A3: อจลญา พิกุลแก้ว 1TB-23110015 | D3: =IF(ISNUMBER(LEFT(A3,1)*1),LEFT(A3,FIND(" ",A3)-1),RIGHT(A3,LEN(A3)-FIND("@",SUBSTITUTE(A3," ","@",LEN(A3)-LEN(SUBSTITUTE(A3," ","")))))) -> 1TB-23110015 | G3: =TRIM(SUBSTITUTE(A3, D3, "")) -> อจลญา พิกุลแก้ว
A4: ไพโรจน์ ปาเกลือ 1TB-23120006 | D4: =IF(ISNUMBER(LEFT(A4,1)*1),LEFT(A4,FIND(" ",A4)-1),RIGHT(A4,LEN(A4)-FIND("@",SUBSTITUTE(A4," ","@",LEN(A4)-LEN(SUBSTITUTE(A4," ","")))))) -> 1TB-23120006 | G4: =TRIM(SUBSTITUTE(A4, D4, "")) -> ไพโรจน์ ปาเกลือ
A5: มนตรี ศรีเพ็ชร์ 1TB-24010003 | D5: =IF(ISNUMBER(LEFT(A5,1)*1),LEFT(A5,FIND(" ",A5)-1),RIGHT(A5,LEN(A5)-FIND("@",SUBSTITUTE(A5," ","@",LEN(A5)-LEN(SUBSTITUTE(A5," ","")))))) -> 1TB-24010003 | G5: =TRIM(SUBSTITUTE(A5, D5, "")) -> มนตรี ศรีเพ็ชร์
A6: บจ.เค.พี.เจนเนอเรชั่น กรุ๊ป 1TB-24010004 | D6: =IF(ISNUMBER(LEFT(A6,1)*1),LEFT(A6,FIND(" ",A6)-1),RIGHT(A6,LEN(A6)-FIND("@",SUBSTITUTE(A6," ","@",LEN(A6)-LEN(SUBSTITUTE(A6," ","")))))) -> 1TB-24010004 | G6: =TRIM(SUBSTITUTE(A6, D6, "")) -> บจ.เค.พี.เจนเนอเรชั่น กรุ๊ป
A7: ณัฎรดา ทวดอาจ NTB-23110001 | D7: =IF(ISNUMBER(LEFT(A7,1)*1),LEFT(A7,FIND(" ",A7)-1),RIGHT(A7,LEN(A7)-FIND("@",SUBSTITUTE(A7," ","@",LEN(A7)-LEN(SUBSTITUTE(A7," ","")))))) -> NTB-23110001 | G7: =TRIM(SUBSTITUTE(A7, D7, "")) -> ณัฎรดา ทวดอาจ
A8: กฤตติกา จงเจริญ NTB-24010001 | D8: =IF(ISNUMBER(LEFT(A8,1)*1),LEFT(A8,FIND(" ",A8)-1),RIGHT(A8,LEN(A8)-FIND("@",SUBSTITUTE(A8," ","@",LEN(A8)-LEN(SUBSTITUTE(A8," ","")))))) -> NTB-24010001 | G8: =TRIM(SUBSTITUTE(A8, D8, "")) -> กฤตติกา จงเจริญ
A9: นงลักษณ์ อุทัย 6TB-24010006 | D9: =IF(ISNUMBER(LEFT(A9,1)*1),LEFT(A9,FIND(" ",A9)-1),RIGHT(A9,LEN(A9)-FIND("@",SUBSTITUTE(A9," ","@",LEN(A9)-LEN(SUBSTITUTE(A9," ","")))))) -> 6TB-24010006 | G9: =TRIM(SUBSTITUTE(A9, D9, "")) -> นงลักษณ์ อุทัย
A10: บดินทร์ ยางราชย์ 3TB-24010001 | D10: =IF(ISNUMBER(LEFT(A10,1)*1),LEFT(A10,FIND(" ",A10)-1),RIGHT(A10,LEN(A10)-FIND("@",SUBSTITUTE(A10," ","@",LEN(A10)-LEN(SUBSTITUTE(A10," ","")))))) -> 3TB-24010001 | G10: =TRIM(SUBSTITUTE(A10, D10, "")) -> บดินทร์ ยางราชย์
A11: ณัฐวุฒิ โอสระคู 3TB-24010009 | D11: =IF(ISNUMBER(LEFT(A11,1)*1),LEFT(A11,FIND(" ",A11)-1),RIGHT(A11,LEN(A11)-FIND("@",SUBSTITUTE(A11," ","@",LEN(A11)-LEN(SUBSTITUTE(A11," ","")))))) -> 3TB-24010009 | G11: =TRIM(SUBSTITUTE(A11, D11, "")) -> ณัฐวุฒิ โอสระคู
A12: ดอน วัสขุนทด 5TB-231202160 | D12: =IF(ISNUMBER(LEFT(A12,1)*1),LEFT(A12,FIND(" ",A12)-1),RIGHT(A12,LEN(A12)-FIND("@",SUBSTITUTE(A12," ","@",LEN(A12)-LEN(SUBSTITUTE(A12," ","")))))) -> 5TB-231202160 | G12: =TRIM(SUBSTITUTE(A12, D12, "")) -> ดอน วัสขุนทด
... A2694: กฤษณนันท์ นันจรูญ 3TV-24120026 | D2694: =IF(ISNUMBER(LEFT(A2694,1)*1),LEFT(A2694,FIND(" ",A2694)-1),RIGHT(A2694,LEN(A2694)-FIND("@",SUBSTITUTE(A2694," ","@",LEN(A2694)-LEN(SUBSTITUTE(A2694," ","")))))) -> 3TV-24120026 | G2694: =TRIM(SUBSTITUTE(A2694, D2694, "")) -> กฤษณนันท์ นันจรูญ
G2695: =TRIM(SUBSTITUTE(A2695, D2695, ""))
A2698: 1

Sheet หมายเหตุ
A1: อิสรีย์ พวงสุดรักษ์ | B1: 358.45 | C1: มีคืนไม่มีรับ
A3: โอยยิ้น แซ่โต๋ว | B3: 7366.95 | C3: รับปี 66

Sheet 5411156633 (2)
B1: บริษัท เอกสหกรุ๊ป ออโตโมบิล จำกัด หน้า : 1
B2: รายงานแยกประเภททั่วไป
B3: วันที่จาก | C3: 1 ม.ค. 2567 | D3: ถึง | E3: 31 ธ.ค. 2567 วันที่ : 26/03/2568
B4: เลขที่บัญชี | C4: 2205-04-00 | D4: ถึง | E4: 2205-04-00 เลือกแผนก *
B5: วันที่ | C5: สมุด | D5: ใบสำคัญ | E5: คำอธิบาย | G5: เดบิต | H5: เครดิต | I5: สถานะ | J5: ยอดคงเหลือ
B6: 2205-04-00 | D6: เงินรับมัดจำ-ค่าอะไหล่และบริการ | J6: -418078.64
B7: 243619 | C7: รับ | D7: RVSR6701-001 | E7: นพคุณ สุขรักษาวงษ์ 3TB-23120404 | H7: 13000 | J7: -431078.64
B8: 243621 | C8: รับ | D8: RVSH6701-002 | E8: นพดล พึ่งเกาะ 5TB-23120247 | G8: 975 | J8: -430103.64
B9: 243621 | C9: รับ | D9: RVSS6701-001 | E9: อจลญา พิกุลแก้ว 1TB-23110015 | G9: 6700 | J9: -423403.64
B10: 243621 | C10: รับ | D10: RVSS6701-001 | E10: ไพโรจน์ ปาเกลือ 1TB-23120006 | G10: 3000 | J10: -420403.64
B11: 243621 | C11: รับ | D11: RVSS6701-001 | E11: มนตรี ศรีเพ็ชร์ 1TB-24010003 | H11: 5000 | J11: -425403.64
B12: 243621 | C12: รับ | D12: RVSS6701-001 | E12: บจ.เค.พี.เจนเนอเรชั่น กรุ๊ป 1TB-24010004 | H12: 2000 | J12: -427403.64
B13: 243622 | C13: รับ | D13: RVSN6701-001 | E13: ณัฎรดา ทวดอาจ NTB-23110001 | G13: 2500 | J13: -424903.64
B14: 243622 | C14: รับ | D14: RVSN6701-001 | E14: กฤตติกา จงเจริญ NTB-24010001 | H14: 3000 | J14: -427903.64
B15: 243622 | C15: รับ | D15: RVSP6701-003 | E15: นงลักษณ์ อุทัย 6TB-24010006 | H15: 20000 | J15: -447903.64
B16: 243622 | C16: รับ | D16: RVSR6701-003 | E16: บดินทร์ ยางราชย์ 3TB-24010001 | H16: 224.7 | J16: -448128.34
B17: 243622 | C17: รับ | D17: RVSR6701-003 | E17: ณัฐวุฒิ โอสระคู 3TB-24010009 | H17: 652.7 | J17: -448781.04
B18: 243623 | C18: รับ | D18: RVSH6701-003 | E18: ดอน วัสขุนทด 5TB-231202160 | G18: 1304.06 | J18: -447476.98
B19: 243623 | C19: รับ | D19: RVSH6701-003 | E19: ฐานุตรี หนูกระโทก 5TB-24010001 | H19: 3860.03 | J19: -451337.01
B20: 243623 | C20: รับ | D20: RVSH6701-004 | E20: มานิต ก่ำพิมาย 5TB-23120272 | G20: 6663.75 | J20: -444673.26
B21: 243623 | C21: รับ | D21: RVSH6701-004 | E21: สมศักดิ์ น้อยแสง 5TB-24010020 | H21: 7687.95 | J21: -452361.21
B22: 243623 | C22: รับ | D22: RVSH6701-004 | E22: กุหลาบ ช่วยพิมาย 5TB-24010038 | H22: 11688.68 | J22: -464049.89
B23: 243623 | C23: รับ | D23: RVSP6701-004 | E23: เสกสิทธิ์ สมม่วง 6TB-24010009 | H23: 1800 | J23: -465849.89
B24: 243623 | C24: รับ | D24: RVSR6701-004 | E24: ประภาพรรณ เนาวเพ็ชร์ 3TB-23120392 | G24: 973.7 | J24: -464876.19
B25: 243624 | C25: รับ | D25: RVSH6701-005 | E25: วิฑูรย์ ทองทา 5TB-24010052 | G25: 326 | J25: -464550.19
B26: 243624 | C26: รับ | D26: RVSH6701-005 | E26: กุหลาบ ช่วยพิมาย 5TB-24010038 | G26: 11688.68 | J26: -452861.51
B27: 243624 | C27: รับ | D27: RVSH6701-005 | E27: วิฑูรย์ ทองทา 5TB-24010053 | H27: 326.35 | J27: -453187.86
B28: 243624 | C28: รับ | D28: RVSH6701-005 | E28: วิฑูรย์ ทองทา 5TB-24010052 | H28: 326 | J28: -453513.86
B29: 243624 | C29: รับ | D29: RVSR6701-005 | E29: หจก.วีระพลออโต้เซอร์วิส 3TB-24010027 | H29: 4700 | J29: -458213.86
B30: 243624 | C30: รับ | D30: RVSR6701-005 | E30: อดิศักดิ์ แสงนาค 3TB-24010037 | H30: 4400 | J30: -462613.86
B31: 243624 | C31: รับ | D31: RVSR6701-005 | E31: จักรกฤษณ์ กิจสมชีพ 3TB-24010038 | H31: 492.2 | J31: -463106.06
B32: 243624 | C32: รับ | D32: RVSR6701-005 | E32: อินทิชา บุญชิต 3TB-24010041 | H32: 144.45 | J32: -463250.51
B33: 243624 | C33: รับ | D33: RVSR6701-006 | E33: บดินทร์ ยางราชย์ 3TB-24010001 | G33: 224.7 | J33: -463025.81
B34: 243625 | C34: รับ | D34: RVSH6701-006 | E34: ชิดชัย ประจิตร 5TB-23120273 | G34: 1885 | J34: -461140.81
B35: 243625 | C35: รับ | D35: RVSH6701-006 | E35: ชิดชัย ประจิตร 5TB-23120275 | G35: 1890 | J35: -459250.81
B36: 243625 | C36: รับ | D36: RVSP6701-006 | E36: อาคม เกิดในแก้ว 6TB-24010028 | H36: 1872.5 | J36: -461123.31
B37: 243625 | C37: รับ | D37: RVSR6701-007 | E37: รัตนาภรณ์ รัตนเพช 3TB-23120411 | G37: 3000 | J37: -458123.31
B38: 243627 | C38: รับ | D38: RVSH6701-007 | E38: ประชา มุ่งยอดกลาง 5TB-23110348 | G38: 347.75 | J38: -457775.56
B39: 243627 | C39: รับ | D39: RVSH6701-007 | E39: ฐานุตรี หนุกระโทก 5TB-24010007 | G39: 3860.03 | J39: -453915.53
B40: 243627 | C40: รับ | D40: RVSH6701-007 | E40: ธนาเทพ ศรียางนอก (ร้านเทพทอง) 5TB-24010082 | H40: 3222 | J40: -457137.53
...
